<?xml version="1.0" ?>
<!-- =================================================================================== -->
<!-- |    This document was autogenerated by xacro from meu.xacro                      | -->
<!-- |    EDITING THIS FILE BY HAND IS NOT RECOMMENDED                                 | -->
<!-- =================================================================================== -->
<robot name="robot">
    <!-- <xacro:include filename="$(find neeeilit)/urdf/macros.xacro" /> -->
    <link name="base_link">
        <visual>
            <origin rpy="0.0 0.0 0.0" xyz="0.0 0.0 0.0" />
            <geometry>
                <box size="1 1 1" />
            </geometry>
        </visual>
        <collision>
            <origin rpy="0.0 0.0 0.0" xyz="0.0 0.0 0" />
            <geometry>
                <box size="1 1 1" />
            </geometry>
        </collision>
        <!-- <inertial>
            <mass value="1024"/>
            <inertia 
                ixx="170.667" ixy="0.0" ixz="0.0"
                iyy="170.667" iyz="0.0"
                izz="170.667"/>
        </inertial> -->
        <inertial>
            <mass value="0.1" />
            <origin xyz="0 0 0" rpy="0 0 0" />
            <inertia ixx="0.03" iyy="0.03" izz="0.03" ixy="0.0" ixz="0.0" iyz="0.0" />
        </inertial>
    </link>
    <link name="base_to_joint1">
        <visual>
            <origin rpy="0 0 0.0" xyz="0 0 0.18" />
            <geometry>
                <cylinder length="0.36" radius="0.4" />
            </geometry>
        </visual>
        <collision>
            <origin rpy="0 0 0" xyz="0 0 0.18" />
            <geometry>
                <cylinder length="0.36" radius="0.4" />
            </geometry>
        </collision>
        <inertial>
            <mass value="1" />
            <inertia ixx="0.06" ixy="0.0" ixz="0.0" iyy="0.06" iyz="0.0" izz="0.25" />
            <origin xyz="0 0 0" rpy="0 0 0" />
        </inertial>
    </link>
    <joint name="joint1" type="revolute">
        <origin rpy="0 0 0" xyz="0 0 0.5" />
        <parent link="base_link" />
        <child link="base_to_joint1" />
        <axis xyz="0 0 1" />
        <limit effort="1000.0" lower="-1.57" upper="1.57" velocity="0.5" />
    </joint>
    <transmission name="joint1_transmission">
        <type>transmission_interface/SimpleTransmission</type>
        <joint name="joint1">
            <hardwareInterface>hardware_interface/EffortJointInterface</hardwareInterface>
        </joint>
        <actuator name="joint_motor1">
            <hardwareInterface>hardware_interface/EffortJointInterface</hardwareInterface>
            <mechanicalReduction>1</mechanicalReduction>
        </actuator>
    </transmission>
    <link name="joint1_to_joint2">
        <visual>
            <origin rpy="0 0 0.0" xyz="0 0 0.46" />
            <geometry>
                <cylinder length="0.92" radius="0.15" />
            </geometry>
        </visual>
        <collision>
            <origin rpy="0 0 0" xyz="0 0 0.46" />
            <geometry>
                <cylinder length="0.92" radius="0.15" />
            </geometry>
        </collision>
        <inertial>
            <mass value="57.906" />
            <inertia ixx="12.679" ixy="0.0" ixz="0.0" iyy="12.679" iyz="0.0" izz="0.651" />
            <origin xyz="0 0 0" rpy="0 0 0" />
        </inertial>
    </link>
    <joint name="joint2" type="revolute">
        <origin rpy="0 0 0" xyz="0 0 0.36" />
        <parent link="base_to_joint1" />
        <child link="joint1_to_joint2" />
        <axis xyz="0 1 0" />
        <limit effort="1000.0" lower="-1.57" upper="1.57" velocity="0.5" />
    </joint>
    <transmission name="joint2_transmission">
        <type>transmission_interface/SimpleTransmission</type>
        <joint name="joint2">
            <hardwareInterface>hardware_interface/EffortJointInterface</hardwareInterface>
        </joint>
        <actuator name="joint_motor2">
            <hardwareInterface>hardware_interface/EffortJointInterface</hardwareInterface>
            <mechanicalReduction>1</mechanicalReduction>
        </actuator>
    </transmission>
    <link name="joint2_to_joint3">
        <visual>
            <origin rpy="0 0 0.0" xyz="0 0 0.385" />
            <geometry>
                <cylinder length="0.77" radius="0.125" />
            </geometry>
        </visual>
        <collision>
            <origin rpy="0 0 0" xyz="0 0 0.385" />
            <geometry>
                <cylinder length="0.77" radius="0.125" />
            </geometry>
        </collision>
        <inertial>
            <mass value="57.906" />
            <inertia ixx="12.679" ixy="0.0" ixz="0.0" iyy="12.679" iyz="0.0" izz="0.651" />
            <origin xyz="0 0 0" rpy="0 0 0" />
        </inertial>
    </link>
    <joint name="joint3" type="revolute">
        <origin rpy="0 0 0" xyz="0 0 0.92" />
        <parent link="joint1_to_joint2" />
        <child link="joint2_to_joint3" />
        <axis xyz="0 1 0" />
        <limit effort="1000.0" lower="-1.57" upper="1.57" velocity="0.5" />
    </joint>
    <transmission name="joint3_transmission">
        <type>transmission_interface/SimpleTransmission</type>
        <joint name="joint3">
            <hardwareInterface>hardware_interface/EffortJointInterface</hardwareInterface>
        </joint>
        <actuator name="joint_motor3">
            <hardwareInterface>hardware_interface/EffortJointInterface</hardwareInterface>
            <mechanicalReduction>1</mechanicalReduction>
        </actuator>
    </transmission>
    <link name="joint3_to_joint4">
        <visual>
            <origin rpy="0 0 0.0" xyz="0 0 0.075" />
            <geometry>
                <cylinder length="0.15" radius="0.075" />
            </geometry>
        </visual>
        <collision>
            <origin rpy="0 0 0" xyz="0 0 0.075" />
            <geometry>
                <cylinder length="0.15" radius="0.075" />
            </geometry>
        </collision>
        <inertial>
            <mass value="57.906" />
            <inertia ixx="12.679" ixy="0.0" ixz="0.0" iyy="12.679" iyz="0.0" izz="0.651" />
            <origin xyz="0 0 0" rpy="0 0 0" />
        </inertial>
    </link>
    <joint name="joint4" type="revolute">
        <origin rpy="0 0 0" xyz="0 0 0.77" />
        <parent link="joint2_to_joint3" />
        <child link="joint3_to_joint4" />
        <axis xyz="0 1 0" />
        <limit effort="1000.0" lower="-1.57" upper="1.57" velocity="0.5" />
    </joint>
    <transmission name="joint4_transmission">
        <type>transmission_interface/SimpleTransmission</type>
        <joint name="joint4">
            <hardwareInterface>hardware_interface/EffortJointInterface</hardwareInterface>
        </joint>
        <actuator name="joint_motor4">
            <hardwareInterface>hardware_interface/EffortJointInterface</hardwareInterface>
            <mechanicalReduction>1</mechanicalReduction>
        </actuator>
    </transmission>
    <link name="joint4_to_tool">
        <visual>
            <origin rpy="0 0 0.0" xyz="0 0 0.075" />
            <geometry>
                <cylinder length="0.15" radius="0.05" />
            </geometry>
        </visual>
        <collision>
            <origin rpy="0 0 0" xyz="0 0 0.075" />
            <geometry>
                <cylinder length="0.15" radius="0.05" />
            </geometry>
        </collision>
        <inertial>
            <mass value="57.906" />
            <inertia ixx="12.679" ixy="0.0" ixz="0.0" iyy="12.679" iyz="0.0" izz="0.651" />
            <origin xyz="0 0 0" rpy="0 0 0" />
        </inertial>
    </link>
    <joint name="tool" type="revolute">
        <origin rpy="0 0 0" xyz="0 0 0.15" />
        <parent link="joint3_to_joint4" />
        <child link="joint4_to_tool" />
        <axis xyz="0 1 0" />
        <limit effort="1000.0" lower="-1.57" upper="1.57" velocity="0.5" />
    </joint>
    <transmission name="tool_transmission">
        <type>transmission_interface/SimpleTransmission</type>
        <joint name="tool">
            <hardwareInterface>hardware_interface/EffortJointInterface</hardwareInterface>
        </joint>
        <actuator name="tool_motor">
            <hardwareInterface>hardware_interface/EffortJointInterface</hardwareInterface>
            <mechanicalReduction>1</mechanicalReduction>
        </actuator>
    </transmission>
    <!-- Add ROS plugin so we can interact with our robot -->
    <gazebo>
        <plugin filename="libgazebo_ros_control.so" name="gazebo_ros_control">
            <robotNamespace>/</robotNamespace>
        </plugin>
    </gazebo>
</robot>

